{
  "schema_version": "1.4.0",
  "id": "GHSA-6jgw-rgmm-7cv6",
  "modified": "2024-10-15T15:30:56Z",
  "published": "2024-10-15T15:30:56Z",
  "aliases": [
    "CVE-2024-9979"
  ],
  "details": "A flaw was found in PyO3. This vulnerability causes a use-after-free issue, potentially leading to memory corruption or crashes via unsound borrowing from weak Python references.",
  "severity": [
    {
      "type": "CVSS_V3",
      "score": "CVSS:3.1/AV:L/AC:L/PR:L/UI:N/S:U/C:L/I:L/A:L"
    }
  ],
  "affected": [

  ],
  "references": [
    {
      "type": "ADVISORY",
      "url": "https://nvd.nist.gov/vuln/detail/CVE-2024-9979"
    },
    {
      "type": "WEB",
      "url": "https://github.com/PyO3/pyo3/pull/4590"
    },
    {
      "type": "WEB",
      "url": "https://access.redhat.com/security/cve/CVE-2024-9979"
    },
    {
      "type": "WEB",
      "url": "https://bugzilla.redhat.com/show_bug.cgi?id=2318646"
    },
    {
      "type": "WEB",
      "url": "https://crates.io/crates/pyo3"
    },
    {
      "type": "WEB",
      "url": "https://rustsec.org/advisories/RUSTSEC-2024-0378.html"
    }
  ],
  "database_specific": {
    "cwe_ids": [
      "CWE-416"
    ],
    "severity": "MODERATE",
    "github_reviewed": false,
    "github_reviewed_at": null,
    "nvd_published_at": "2024-10-15T14:15:05Z"
  }
}